Workbook

Sheet README
B2: FutureWorld Robotics — GASB Financial Model, Version 2
B4: Illustrative GASB enterprise-fund recast of Financial Model v13 · prepared by Sorphoan (Jack) Ear · June 2026
B5: What changed in Version 2
B6: 1. Added Management’s Discussion & Analysis (MD&A) as required supplementary information, with a condensed-financials table linked to the statements.
B7: 2. Split the direct-method operating cash flow into separate "cash paid to suppliers" and "cash paid to employees" lines, per GASB presentation.
B8: Purpose
B9: This workbook recasts the FutureWorld Robotics five-year projection (Financial Model v13) into governmental (GASB) enterprise-fund form. v13 is unchanged and remains the for-profit business model; this GASB version is a separate file for a public-entity (government or public-university affiliated) reporting scenario.
B10: How it is built
B11: The "Source (from v13)" tab holds the line items carried from v13 (blue = inputs). Every statement is formula-driven from it (green = cross-sheet links, black = calculations), so the statements tie out and update if the source changes.
B12: Key GASB recast points
B13: Income tax removed (governmental tax-exempt); equity recast as capital contributions; net position in three components; operating vs nonoperating split with depreciation as an operating expense; direct-method four-category cash flow with reconciliation; deferred outflows/inflows, pension/OPEB, GASB 87/96 and unearned revenue shown as captioned placeholders pending real inputs.
B14: Tabs
... B17: Illustrative planning model, not audited financial statements and not a forecast. Confirm treatment with a CPA before reliance.

Sheet MD&A
B2: MANAGEMENT'S DISCUSSION AND ANALYSIS (UNAUDITED)
B3: Required supplementary information · illustrative · $ unless noted
B5: Overview of the financial statements
B6: This discussion introduces FutureWorld Robotics’ basic financial statements, presented as an enterprise fund using the economic resources measurement focus and the accrual basis of accounting. The basic statements are the Statement of Net Position, the Statement of Revenues, Expenses, and Changes in Net Position, and the Statement of Cash Flows, accompanied by notes.
B8: Condensed financial information
B9: $ | C9: 2027 | D9: 2028 | E9: 2029 | F9: 2030 | G9: 2031
B10: Total operating revenues | C10: ='Stmt Rev Exp & Net Position'!C24 -> 35470125 | D10: ='Stmt Rev Exp & Net Position'!D24 -> 40375150 | E10: ='Stmt Rev Exp & Net Position'!E24 -> 45904150 | F10: ='Stmt Rev Exp & Net Position'!F24 -> 49027875 | G10: ='Stmt Rev Exp & Net Position'!G24 -> 50756225
B11: Operating income (loss) | C11: ='Stmt Rev Exp & Net Position'!C45 -> 11021956 | D11: ='Stmt Rev Exp & Net Position'!D45 -> 14127224 | E11: ='Stmt Rev Exp & Net Position'!E45 -> 16776852 | F11: ='Stmt Rev Exp & Net Position'!F45 -> 17932819 | G11: ='Stmt Rev Exp & Net Position'!G45 -> 20072472
B12: Change in net position | C12: ='Stmt Rev Exp & Net Position'!C55 -> 26841956 | D12: ='Stmt Rev Exp & Net Position'!D55 -> 13947224 | E12: ='Stmt Rev Exp & Net Position'!E55 -> 16596852 | F12: ='Stmt Rev Exp & Net Position'!F55 -> 17752819 | G12: ='Stmt Rev Exp & Net Position'!G55 -> 19892472
B13: Total assets | C13: ='Stmt Net Position'!C12 -> 32841956 | D13: ='Stmt Net Position'!D12 -> 46789180 | E13: ='Stmt Net Position'!E12 -> 63386032 | F13: ='Stmt Net Position'!F12 -> 81138851 | G13: ='Stmt Net Position'!G12 -> 1.0103132e+08
B14: Long-term debt | C14: ='Stmt Net Position'!C23 -> 6000000 | D14: ='Stmt Net Position'!D23 -> 6000000 | E14: ='Stmt Net Position'!E23 -> 6000000 | F14: ='Stmt Net Position'!F23 -> 6000000 | G14: ='Stmt Net Position'!G23 -> 6000000
B15: Total net position (end of year) | C15: ='Stmt Net Position'!C35 -> 26841956 | D15: ='Stmt Net Position'!D35 -> 40789180 | E15: ='Stmt Net Position'!E35 -> 57386032 | F15: ='Stmt Net Position'!F35 -> 75138851 | G15: ='Stmt Net Position'!G35 -> 95031323
B17: Financial position and results of operations
B18: Total net position grows each year of the projection, from $26.8M at the end of 2027 to $95.0M by 2031, reflecting positive changes in net position in every year. Year 2027 includes a $16.0M capital contribution that establishes the fund. Operating revenues rise from $35.5M (2027) to $50.8M (2031) as attendance ramps and the membership and business lines mature, while operating income remains strongly positive throughout. Because a governmental enterprise fund is tax-exempt, results are reported without income tax.
B20: Capital asset and debt administration
B21: Capital assets, net of accumulated depreciation, are $15.5M at the end of 2027 and $11.4M by 2031, reflecting initial build-out and fleet investment of $18.6M in 2027 followed by annual refresh capital spending net of depreciation. Long-term debt is a $6.0M placeholder facility carried throughout the projection; in a governmental structure this would typically be issued as tax-exempt revenue bonds, with interest reported within capital and related financing activities. Net investment in capital assets (capital assets net of related debt) declines from $9.5M to $5.4M as assets depreciate.
B23: Economic factors and outlook
B24: The projection assumes a five-year price-skim curve and an attendance ramp from 165,000 to 270,000 annual visits. Attendance and willingness-to-pay are the most sensitive inputs; the model’s scenario set (in v13) tests downside cases that remain cash-positive. Figures are illustrative and should be validated against local market data.

Sheet Stmt Net Position
B2: STATEMENT OF NET POSITION
B3: At year-end · classified · illustrative
B5: $ unless noted | C5: 2027 | D5: 2028 | E5: 2029 | F5: 2030 | G5: 2031
B7: ASSETS
B8: Current assets:
B9: Cash & cash equivalents | C9: ='Stmt Cash Flows'!C30 -> 17372756 | D9: ='Stmt Cash Flows'!D30 -> 32134447 | E9: ='Stmt Cash Flows'!E30 -> 50057432 | F9: ='Stmt Cash Flows'!F30 -> 69648051 | G9: ='Stmt Cash Flows'!G30 -> 89619989
B10: Noncurrent assets:
B11: Capital assets, net of depreciation | C11: ='Source (from v13)'!C44 -> 15469200 | D11: ='Source (from v13)'!D44 -> 14654733 | E11: ='Source (from v13)'!E44 -> 13328600 | F11: ='Source (from v13)'!F44 -> 11490800 | G11: ='Source (from v13)'!G44 -> 11411333
B12: Total assets | C12: =C9+C11 -> 32841956 | D12: =D9+D11 -> 46789180 | E12: =E9+E11 -> 63386032 | F12: =F9+F11 -> 81138851 | G12: =G9+G11 -> 1.0103132e+08
B14: DEFERRED OUTFLOWS OF RESOURCES
B15: Deferred outflows (pensions, OPEB, leases) | C15: 0 | D15: 0 | E15: 0 | F15: 0 | G15: 0
B16: Total deferred outflows of resources | C16: =C15 -> 0 | D16: =D15 -> 0 | E16: =E15 -> 0 | F16: =F15 -> 0 | G16: =G15 -> 0
B18: LIABILITIES
B19: Current liabilities:
B20: Unearned revenue (memberships/deposits) | C20: 0 | D20: 0 | E20: 0 | F20: 0 | G20: 0
B21: Current portion of long-term debt | C21: 0 | D21: 0 | E21: 0 | F21: 0 | G21: 0
B22: Noncurrent liabilities:
B23: Long-term debt (revenue bonds) | C23: ='Source (from v13)'!C46 -> 6000000 | D23: ='Source (from v13)'!D46 -> 6000000 | E23: ='Source (from v13)'!E46 -> 6000000 | F23: ='Source (from v13)'!F46 -> 6000000 | G23: ='Source (from v13)'!G46 -> 6000000
B24: Net pension / OPEB liability | C24: 0 | D24: 0 | E24: 0 | F24: 0 | G24: 0
B25: Total liabilities | C25: =C20+C21+C23+C24 -> 6000000 | D25: =D20+D21+D23+D24 -> 6000000 | E25: =E20+E21+E23+E24 -> 6000000 | F25: =F20+F21+F23+F24 -> 6000000 | G25: =G20+G21+G23+G24 -> 6000000
B27: DEFERRED INFLOWS OF RESOURCES
B28: Deferred inflows (pensions, leases) | C28: 0 | D28: 0 | E28: 0 | F28: 0 | G28: 0
B29: Total deferred inflows of resources | C29: =C28 -> 0 | D29: =D28 -> 0 | E29: =E28 -> 0 | F29: =F28 -> 0 | G29: =G28 -> 0
B31: NET POSITION
B32: Net investment in capital assets | C32: =C11-C23-C21 -> 9469200 | D32: =D11-D23-D21 -> 8654733.3 | E32: =E11-E23-E21 -> 7328600 | F32: =F11-F23-F21 -> 5490800 | G32: =G11-G23-G21 -> 5411333.3
B33: Restricted | C33: 0 | D33: 0 | E33: 0 | F33: 0 | G33: 0
B34: Unrestricted | C34: ='Stmt Rev Exp & Net Position'!C58-C32-C33 -> 17372756 | D34: ='Stmt Rev Exp & Net Position'!D58-D32-D33 -> 32134447 | E34: ='Stmt Rev Exp & Net Position'!E58-E32-E33 -> 50057432 | F34: ='Stmt Rev Exp & Net Position'!F58-F32-F33 -> 69648051 | G34: ='Stmt Rev Exp & Net Position'!G58-G32-G33 -> 89619989
B35: Total net position | C35: =C32+C33+C34 -> 26841956 | D35: =D32+D33+D34 -> 40789180 | E35: =E32+E33+E34 -> 57386032 | F35: =F32+F33+F34 -> 75138851 | G35: =G32+G33+G34 -> 95031323
B37: Check: Assets+DefOut − (Liab+DefIn+NetPos) | C37: =C12+C16-(C25+C29+C35) -> 0 | D37: =D12+D16-(D25+D29+D35) -> 0 | E37: =E12+E16-(E25+E29+E35) -> 0 | F37: =F12+F16-(F25+F29+F35) -> 0 | G37: =G12+G16-(G25+G29+G35) -> 0

Sheet Stmt Rev Exp & Net Position
B2: STATEMENT OF REVENUES, EXPENSES, AND CHANGES IN NET POSITION
B3: FutureWorld Robotics enterprise fund · GASB recast of v13 · five-year projection · illustrative
B5: $ unless noted | C5: 2027 | D5: 2028 | E5: 2029 | F5: 2030 | G5: 2031
B7: OPERATING REVENUES
B8: Admission (net of comp/discount) | C8: ='Source (from v13)'!C7 -> 19985625 | D8: ='Source (from v13)'!D7 -> 20773650 | E8: ='Source (from v13)'!E7 -> 22227150 | F8: ='Source (from v13)'!F7 -> 22336875 | G8: ='Source (from v13)'!G7 -> 21456225
B9: Photo experiences | C9: ='Source (from v13)'!C8 -> 1320000 | D9: ='Source (from v13)'!D8 -> 1480000 | E9: ='Source (from v13)'!E8 -> 1760000 | F9: ='Source (from v13)'!F8 -> 2000000 | G9: ='Source (from v13)'!G8 -> 2160000
B10: Retail / merchandise | C10: ='Source (from v13)'!C9 -> 1485000 | D10: ='Source (from v13)'!D9 -> 1665000 | E10: ='Source (from v13)'!E9 -> 1980000 | F10: ='Source (from v13)'!F9 -> 2250000 | G10: ='Source (from v13)'!G9 -> 2430000
B11: Robotic coffee shop | C11: ='Source (from v13)'!C10 -> 990000 | D11: ='Source (from v13)'!D10 -> 1110000 | E11: ='Source (from v13)'!E10 -> 1320000 | F11: ='Source (from v13)'!F10 -> 1500000 | G11: ='Source (from v13)'!G10 -> 1620000
B12: Robotic restaurant | C12: ='Source (from v13)'!C11 -> 1650000 | D12: ='Source (from v13)'!D11 -> 1850000 | E12: ='Source (from v13)'!E11 -> 2200000 | F12: ='Source (from v13)'!F11 -> 2500000 | G12: ='Source (from v13)'!G11 -> 2700000
B13: Robot vending | C13: ='Source (from v13)'!C12 -> 247500 | D13: ='Source (from v13)'!D12 -> 277500 | E13: ='Source (from v13)'!E12 -> 330000 | F13: ='Source (from v13)'!F12 -> 375000 | G13: ='Source (from v13)'!G12 -> 405000
B14: Memberships | C14: ='Source (from v13)'!C13 -> 4792000 | D14: ='Source (from v13)'!D13 -> 6589000 | E14: ='Source (from v13)'!E13 -> 7787000 | F14: ='Source (from v13)'!F13 -> 8386000 | G14: ='Source (from v13)'!G13 -> 8985000
B15: Exhibitor / showcase booths | C15: ='Source (from v13)'!C14 -> 900000 | D15: ='Source (from v13)'!D14 -> 1330000 | E15: ='Source (from v13)'!E14 -> 1800000 | F15: ='Source (from v13)'!F14 -> 2310000 | G15: ='Source (from v13)'!G14 -> 2750000
B16: Sponsorship & naming rights | C16: ='Source (from v13)'!C15 -> 1000000 | D16: ='Source (from v13)'!D15 -> 1300000 | E16: ='Source (from v13)'!E15 -> 1600000 | F16: ='Source (from v13)'!F15 -> 1800000 | G16: ='Source (from v13)'!G15 -> 2000000
B17: Corporate events & private hire | C17: ='Source (from v13)'!C16 -> 1000000 | D17: ='Source (from v13)'!D16 -> 1200000 | E17: ='Source (from v13)'!E16 -> 1400000 | F17: ='Source (from v13)'!F16 -> 1600000 | G17: ='Source (from v13)'!G16 -> 1800000
B18: Conference & event hosting | C18: ='Source (from v13)'!C17 -> 300000 | D18: ='Source (from v13)'!D17 -> 500000 | E18: ='Source (from v13)'!E17 -> 700000 | F18: ='Source (from v13)'!F17 -> 850000 | G18: ='Source (from v13)'!G17 -> 1000000
B19: Education — courses & field trips | C19: ='Source (from v13)'!C18 -> 900000 | D19: ='Source (from v13)'!D18 -> 1100000 | E19: ='Source (from v13)'!E18 -> 1300000 | F19: ='Source (from v13)'!F18 -> 1400000 | G19: ='Source (from v13)'!G18 -> 1500000
... B23: Traveling-exhibit licensing | C23: ='Source (from v13)'!C22 -> 50000 | D23: ='Source (from v13)'!D22 -> 100000 | E23: ='Source (from v13)'!E22 -> 200000 | F23: ='Source (from v13)'!F22 -> 300000 | G23: ='Source (from v13)'!G22 -> 400000
B24: Total operating revenues | C24: =SUM(C8:C23) -> 35470125 | D24: =SUM(D8:D23) -> 40375150 | E24: =SUM(E8:E23) -> 45904150 | F24: =SUM(F8:F23) -> 49027875 | G24: =SUM(G8:G23) -> 50756225
B26: OPERATING EXPENSES
B27: Payroll & staff | C27: ='Source (from v13)'!C26 -> 6941250 | D27: ='Source (from v13)'!D26 -> 7562500 | E27: ='Source (from v13)'!E26 -> 8668750 | F27: ='Source (from v13)'!F26 -> 8946250 | G27: ='Source (from v13)'!G26 -> 9332500
B28: Rent / lease | C28: ='Source (from v13)'!C27 -> 1620000 | D28: ='Source (from v13)'!D27 -> 1669000 | E28: ='Source (from v13)'!E27 -> 1719000 | F28: ='Source (from v13)'!F27 -> 1771000 | G28: ='Source (from v13)'!G27 -> 1824000
B29: Utilities | C29: ='Source (from v13)'!C28 -> 600000 | D29: ='Source (from v13)'!D28 -> 620000 | E29: ='Source (from v13)'!E28 -> 640000 | F29: ='Source (from v13)'!F28 -> 660000 | G29: ='Source (from v13)'!G28 -> 680000
B30: Marketing | C30: ='Source (from v13)'!C29 -> 2500000 | D30: ='Source (from v13)'!D29 -> 2000000 | E30: ='Source (from v13)'!E29 -> 1800000 | F30: ='Source (from v13)'!F29 -> 1800000 | G30: ='Source (from v13)'!G29 -> 1800000
B31: Show production & new content | C31: ='Source (from v13)'!C30 -> 800000 | D31: ='Source (from v13)'!D30 -> 900000 | E31: ='Source (from v13)'!E30 -> 1000000 | F31: ='Source (from v13)'!F30 -> 1000000 | G31: ='Source (from v13)'!G30 -> 1000000
B32: Insurance | C32: ='Source (from v13)'!C31 -> 400000 | D32: ='Source (from v13)'!D31 -> 420000 | E32: ='Source (from v13)'!E31 -> 440000 | F32: ='Source (from v13)'!F31 -> 460000 | G32: ='Source (from v13)'!G31 -> 480000
B33: Facility & AV maintenance | C33: ='Source (from v13)'!C32 -> 600000 | D33: ='Source (from v13)'!D32 -> 700000 | E33: ='Source (from v13)'!E32 -> 800000 | F33: ='Source (from v13)'!F32 -> 850000 | G33: ='Source (from v13)'!G32 -> 900000
B34: G&A / other | C34: ='Source (from v13)'!C33 -> 1200000 | D34: ='Source (from v13)'!D33 -> 1300000 | E34: ='Source (from v13)'!E33 -> 1400000 | F34: ='Source (from v13)'!F33 -> 1500000 | G34: ='Source (from v13)'!G33 -> 1600000
B35: Outsourced services | C35: ='Source (from v13)'!C34 -> 930000 | D35: ='Source (from v13)'!D34 -> 1000000 | E35: ='Source (from v13)'!E34 -> 1060000 | F35: ='Source (from v13)'!F34 -> 1120000 | G35: ='Source (from v13)'!G34 -> 1180000
B36: Robot maintenance | C36: ='Source (from v13)'!C35 -> 1634400 | D36: ='Source (from v13)'!D35 -> 1940400 | E36: ='Source (from v13)'!E35 -> 2246400 | F36: ='Source (from v13)'!F35 -> 2552400 | G36: ='Source (from v13)'!G35 -> 2858400
B37: Retail COGS | C37: ='Source (from v13)'!C36 -> 742500 | D37: ='Source (from v13)'!D36 -> 832500 | E37: ='Source (from v13)'!E36 -> 990000 | F37: ='Source (from v13)'!F36 -> 1125000 | G37: ='Source (from v13)'!G36 -> 1215000
B38: F&B COGS | C38: ='Source (from v13)'!C37 -> 1876875 | D38: ='Source (from v13)'!D37 -> 2104375 | E38: ='Source (from v13)'!E37 -> 2502500 | F38: ='Source (from v13)'!F37 -> 2843750 | G38: ='Source (from v13)'!G37 -> 3071250
... B41: Licensing & IP (placeholder) | C41: ='Source (from v13)'!C40 -> 400000 | D41: ='Source (from v13)'!D40 -> 400000 | E41: ='Source (from v13)'!E40 -> 400000 | F41: ='Source (from v13)'!F40 -> 400000 | G41: ='Source (from v13)'!G40 -> 400000
B42: Depreciation & amortization | C42: ='Source (from v13)'!C42 -> 3102800 | D42: ='Source (from v13)'!D42 -> 3614466.7 | E42: ='Source (from v13)'!E42 -> 4126133.3 | F42: ='Source (from v13)'!F42 -> 4637800 | G42: ='Source (from v13)'!G42 -> 2879466.7
B43: Total operating expenses | C43: =SUM(C27:C42) -> 24448169 | D43: =SUM(D27:D42) -> 26247926 | E43: =SUM(E27:E42) -> 29127298 | F43: =SUM(F27:F42) -> 31095056 | G43: =SUM(G27:G42) -> 30683753
B45: Operating income (loss) | C45: =C24-C43 -> 11021956 | D45: =D24-D43 -> 14127224 | E45: =E24-E43 -> 16776852 | F45: =F24-F43 -> 17932819 | G45: =G24-G43 -> 20072472
B47: NONOPERATING REVENUES (EXPENSES)
B48: Grants (nonexchange) | C48: ='Source (from v13)'!C24 -> 300000 | D48: ='Source (from v13)'!D24 -> 300000 | E48: ='Source (from v13)'!E24 -> 300000 | F48: ='Source (from v13)'!F24 -> 300000 | G48: ='Source (from v13)'!G24 -> 300000
B49: Investment income | C49: 0 | D49: 0 | E49: 0 | F49: 0 | G49: 0
B50: Interest expense | C50: =-'Source (from v13)'!C43 -> -480000 | D50: =-'Source (from v13)'!D43 -> -480000 | E50: =-'Source (from v13)'!E43 -> -480000 | F50: =-'Source (from v13)'!F43 -> -480000 | G50: =-'Source (from v13)'!G43 -> -480000
B51: Net nonoperating revenues (expenses) | C51: =C48+C49+C50 -> -180000 | D51: =D48+D49+D50 -> -180000 | E51: =E48+E49+E50 -> -180000 | F51: =F48+F49+F50 -> -180000 | G51: =G48+G49+G50 -> -180000
...

Sheet Stmt Cash Flows
B2: STATEMENT OF CASH FLOWS
B3: Direct method · four GASB categories · illustrative
B5: $ unless noted | C5: 2027 | D5: 2028 | E5: 2029 | F5: 2030 | G5: 2031
B7: CASH FLOWS FROM OPERATING ACTIVITIES
B8: Cash received from customers | C8: ='Stmt Rev Exp & Net Position'!C24 -> 35470125 | D8: ='Stmt Rev Exp & Net Position'!D24 -> 40375150 | E8: ='Stmt Rev Exp & Net Position'!E24 -> 45904150 | F8: ='Stmt Rev Exp & Net Position'!F24 -> 49027875 | G8: ='Stmt Rev Exp & Net Position'!G24 -> 50756225
B9: Cash paid to suppliers | C9: =-('Stmt Rev Exp & Net Position'!C43-'Source (from v13)'!C42-'Source (from v13)'!C26) -> -14404119 | D9: =-('Stmt Rev Exp & Net Position'!D43-'Source (from v13)'!D42-'Source (from v13)'!D26) -> -15070960 | E9: =-('Stmt Rev Exp & Net Position'!E43-'Source (from v13)'!E42-'Source (from v13)'!E26) -> -16332414 | F9: =-('Stmt Rev Exp & Net Position'!F43-'Source (from v13)'!F42-'Source (from v13)'!F26) -> -17511006 | G9: =-('Stmt Rev Exp & Net Position'!G43-'Source (from v13)'!G42-'Source (from v13)'!G26) -> -18471787
B10: Cash paid to employees | C10: =-'Source (from v13)'!C26 -> -6941250 | D10: =-'Source (from v13)'!D26 -> -7562500 | E10: =-'Source (from v13)'!E26 -> -8668750 | F10: =-'Source (from v13)'!F26 -> -8946250 | G10: =-'Source (from v13)'!G26 -> -9332500
B11: Net cash provided by operating activities | C11: =C8+C9+C10 -> 14124756 | D11: =D8+D9+D10 -> 17741690 | E11: =E8+E9+E10 -> 20902986 | F11: =F8+F9+F10 -> 22570619 | G11: =G8+G9+G10 -> 22951938
B13: CASH FLOWS FROM NONCAPITAL FINANCING ACTIVITIES
B14: Grants received | C14: ='Source (from v13)'!C24 -> 300000 | D14: ='Source (from v13)'!D24 -> 300000 | E14: ='Source (from v13)'!E24 -> 300000 | F14: ='Source (from v13)'!F24 -> 300000 | G14: ='Source (from v13)'!G24 -> 300000
B15: Net cash from noncapital financing activities | C15: =C14 -> 300000 | D15: =D14 -> 300000 | E15: =E14 -> 300000 | F15: =F14 -> 300000 | G15: =G14 -> 300000
B17: CASH FLOWS FROM CAPITAL & RELATED FINANCING ACTIVITIES
B18: Capital contributions | C18: ='Source (from v13)'!C48 -> 16000000 | D18: ='Source (from v13)'!D48 -> 0 | E18: ='Source (from v13)'!E48 -> 0 | F18: ='Source (from v13)'!F48 -> 0 | G18: ='Source (from v13)'!G48 -> 0
B19: Proceeds from capital debt | C19: ='Source (from v13)'!C47 -> 6000000 | D19: ='Source (from v13)'!D47 -> 0 | E19: ='Source (from v13)'!E47 -> 0 | F19: ='Source (from v13)'!F47 -> 0 | G19: ='Source (from v13)'!G47 -> 0
B20: Acquisition of capital assets | C20: =-'Source (from v13)'!C45 -> -18572000 | D20: =-'Source (from v13)'!D45 -> -2800000 | E20: =-'Source (from v13)'!E45 -> -2800000 | F20: =-'Source (from v13)'!F45 -> -2800000 | G20: =-'Source (from v13)'!G45 -> -2800000
B21: Interest paid on capital debt | C21: =-'Source (from v13)'!C43 -> -480000 | D21: =-'Source (from v13)'!D43 -> -480000 | E21: =-'Source (from v13)'!E43 -> -480000 | F21: =-'Source (from v13)'!F43 -> -480000 | G21: =-'Source (from v13)'!G43 -> -480000
B22: Net cash from capital & related financing | C22: =C18+C19+C20+C21 -> 2948000 | D22: =D18+D19+D20+D21 -> -3280000 | E22: =E18+E19+E20+E21 -> -3280000 | F22: =F18+F19+F20+F21 -> -3280000 | G22: =G18+G19+G20+G21 -> -3280000
B24: CASH FLOWS FROM INVESTING ACTIVITIES
B25: Investment income received | C25: 0 | D25: 0 | E25: 0 | F25: 0 | G25: 0
B26: Net cash from investing activities | C26: =C25 -> 0 | D26: =D25 -> 0 | E26: =E25 -> 0 | F26: =F25 -> 0 | G26: =G25 -> 0
B28: Net change in cash | C28: =C11+C15+C22+C26 -> 17372756 | D28: =D11+D15+D22+D26 -> 14761690 | E28: =E11+E15+E22+E26 -> 17922986 | F28: =F11+F15+F22+F26 -> 19590619 | G28: =G11+G15+G22+G26 -> 19971938
B29: Cash — beginning of year | C29: =0 -> 0 | D29: =C30 -> 17372756 | E29: =D30 -> 32134447 | F29: =E30 -> 50057432 | G29: =F30 -> 69648051
B30: Cash — end of year | C30: =C29+C28 -> 17372756 | D30: =D29+D28 -> 32134447 | E30: =E29+E28 -> 50057432 | F30: =F29+F28 -> 69648051 | G30: =G29+G28 -> 89619989

Sheet Reconciliation & Bridge
B2: RECONCILIATIONS
B3: GASB operating cash reconciliation + GAAP(v13) → GASB bridge
B5: $ unless noted | C5: 2027 | D5: 2028 | E5: 2029 | F5: 2030 | G5: 2031
B7: A. Reconciliation of operating income to net cash from operating activities
B8: Operating income (loss) | C8: ='Stmt Rev Exp & Net Position'!C45 -> 11021956 | D8: ='Stmt Rev Exp & Net Position'!D45 -> 14127224 | E8: ='Stmt Rev Exp & Net Position'!E45 -> 16776852 | F8: ='Stmt Rev Exp & Net Position'!F45 -> 17932819 | G8: ='Stmt Rev Exp & Net Position'!G45 -> 20072472
B9: Adjustment: depreciation & amortization | C9: ='Source (from v13)'!C42 -> 3102800 | D9: ='Source (from v13)'!D42 -> 3614466.7 | E9: ='Source (from v13)'!E42 -> 4126133.3 | F9: ='Source (from v13)'!F42 -> 4637800 | G9: ='Source (from v13)'!G42 -> 2879466.7
B10: Adjustment: change in working capital | C10: 0 | D10: 0 | E10: 0 | F10: 0 | G10: 0
B11: Net cash provided by operating activities | C11: =C8+C9+C10 -> 14124756 | D11: =D8+D9+D10 -> 17741690 | E11: =E8+E9+E10 -> 20902986 | F11: =F8+F9+F10 -> 22570619 | G11: =G8+G9+G10 -> 22951938
B12: Check vs. cash flow statement | C12: =C11-'Stmt Cash Flows'!C11 -> 0 | D12: =D11-'Stmt Cash Flows'!D11 -> 0 | E12: =E11-'Stmt Cash Flows'!E11 -> 0 | F12: =F11-'Stmt Cash Flows'!F11 -> 0 | G12: =G11-'Stmt Cash Flows'!G11 -> 0
B14: B. Bridge: v13 GAAP net income to GASB change in net position
B15: v13 net income (after tax, for-profit) | C15: ='Source (from v13)'!C51 -> 8131467.2 | D15: ='Source (from v13)'!D51 -> 10460418 | E15: ='Source (from v13)'!E51 -> 12447639 | F15: ='Source (from v13)'!F51 -> 13314614 | G15: ='Source (from v13)'!G51 -> 14919354
B16: Add: income tax removed (govt is tax-exempt) | C16: ='Source (from v13)'!C50 -> 2710489.1 | D16: ='Source (from v13)'!D50 -> 3486806 | E16: ='Source (from v13)'!E50 -> 4149213 | F16: ='Source (from v13)'!F50 -> 4438204.7 | G16: ='Source (from v13)'!G50 -> 4973117.9
B17: Subtotal: income before capital contributions | C17: =C15+C16 -> 10841956 | D17: =D15+D16 -> 13947224 | E17: =E15+E16 -> 16596852 | F17: =F15+F16 -> 17752819 | G17: =G15+G16 -> 19892472
B18: Add: capital contributions (ex-equity financing) | C18: ='Source (from v13)'!C48 -> 16000000 | D18: ='Source (from v13)'!D48 -> 0 | E18: ='Source (from v13)'!E48 -> 0 | F18: ='Source (from v13)'!F48 -> 0 | G18: ='Source (from v13)'!G48 -> 0
B19: Change in net position (GASB) | C19: =C17+C18 -> 26841956 | D19: =D17+D18 -> 13947224 | E19: =E17+E18 -> 16596852 | F19: =F17+F18 -> 17752819 | G19: =G17+G18 -> 19892472
B20: Check vs. SRECNP change in net position | C20: =C19-'Stmt Rev Exp & Net Position'!C55 -> 0 | D20: =D19-'Stmt Rev Exp & Net Position'!D55 -> 0 | E20: =E19-'Stmt Rev Exp & Net Position'!E55 -> 0 | F20: =F19-'Stmt Rev Exp & Net Position'!F55 -> 0 | G20: =G19-'Stmt Rev Exp & Net Position'!G55 -> 0

Sheet Notes
B2: Notes to the Financial Statements (selected)
B4: Illustrative · abbreviated for a work sample
B5: Note 1 — Reporting entity & basis of accounting
B6: FutureWorld Robotics is presented as an enterprise fund / business-type activity. The financial statements are prepared on the economic resources measurement focus and the accrual basis of accounting, in conformity with U.S. GAAP as prescribed by the Governmental Accounting Standards Board (GASB).
B7: Note 2 — Operating vs. nonoperating
B8: Operating revenues result from exchange transactions (admissions, on-site spend, memberships, education, booths, events). Operating expenses include the cost of providing services and depreciation. Grants (nonexchange), investment income, interest expense, and capital contributions are reported as nonoperating or below the operating line.
B9: Note 3 — Capital assets
B10: Capital assets (robots, build-out, AV/IT) are recorded at cost and depreciated straight-line over estimated useful lives: robots 4 years, build-out 15 years, AV/IT 5 years. See the v13 CapEx & Depreciation schedule for the per-vintage roll-forward carried into this model.
B11: Note 4 — Long-term debt
B12: Long-term debt is a $6.0M placeholder facility (interest-only at 8% in v13). In a governmental structure this would typically be refinanced as lower-rate tax-exempt revenue bonds; interest is reported within capital & related financing activities.
B13: Note 5 — Net position
B14: Net position is displayed in three components: net investment in capital assets (capital assets net of related debt), restricted, and unrestricted.
... B16: Net pension and OPEB liabilities (GASB 68/75), lease right-to-use assets and liabilities (GASB 87), and subscription-based IT arrangements (GASB 96), with related deferred outflows/inflows of resources, are presented as captioned placeholders pending actuarial and contract inputs.

Sheet GASB vs GAAP Crosswalk
B2: GASB vs GAAP — CROSSWALK
B3: How the same entity differs under FASB GAAP (v13) and GASB (this model)
B5: Topic | C5: FASB GAAP (v13 business model) | D5: GASB (this model)
B6: Applies to | C6: Private for-profits & nonprofits | D6: State/local govts, public universities — e.g., UC Riverside
B7: Equity section | C7: Paid-in capital + retained earnings | D7: Net position: net investment in capital assets, restricted, unrestricted
B8: Deferred outflows/inflows | C8: Concept does not exist | D8: Distinct 5th & 6th statement elements
B9: Income statement | C9: Revenue → EBITDA → EBIT → net income | D9: Operating income → income before capital contributions → change in net position
B10: Income tax | C10: 25% corporate tax modeled | D10: Tax-exempt — no income tax
B11: Capital from owners | C11: Equity raise ($16M, investors ~1/3) | D11: Capital contributions to the fund
B12: Operating vs nonoperating | C12: Not required | D12: Required; grants, investment income, interest = nonoperating
B13: Interest expense | C13: Within pre-tax operating result | D13: Nonoperating / capital & related financing
B14: Cash flow | C14: Indirect, 3 categories | D14: Direct, 4 categories + reconciliation
B15: Leases | C15: ASC 842 (finance vs operating) | D15: GASB 87 single model (placeholder)
B16: Pensions/OPEB | C16: ASC 715 | D16: GASB 68/75 net liability on face (placeholder)
... B18: MD&A | C18: Not required | D18: Required supplementary information (included)

Sheet Source (from v13)
B2: FUTUREWORLD ROBOTICS — SOURCE DATA (from Financial Model v13)
B3: Blue = hardcoded inputs carried from v13. Source: FutureWorld_Robotics_Financial_Model_v13.xlsx
B5: $ unless noted | C5: 2027 | D5: 2028 | E5: 2029 | F5: 2030 | G5: 2031
B6: OPERATING REVENUES — exchange (GASB)
B7: Admission (net of comp/discount) | C7: 19985625 | D7: 20773650 | E7: 22227150 | F7: 22336875 | G7: 21456225
B8: Photo experiences | C8: 1320000 | D8: 1480000 | E8: 1760000 | F8: 2000000 | G8: 2160000
B9: Retail / merchandise | C9: 1485000 | D9: 1665000 | E9: 1980000 | F9: 2250000 | G9: 2430000
B10: Robotic coffee shop | C10: 990000 | D10: 1110000 | E10: 1320000 | F10: 1500000 | G10: 1620000
B11: Robotic restaurant | C11: 1650000 | D11: 1850000 | E11: 2200000 | F11: 2500000 | G11: 2700000
B12: Robot vending | C12: 247500 | D12: 277500 | E12: 330000 | F12: 375000 | G12: 405000
B13: Memberships | C13: 4792000 | D13: 6589000 | E13: 7787000 | F13: 8386000 | G13: 8985000
B14: Exhibitor / showcase booths | C14: 900000 | D14: 1330000 | E14: 1800000 | F14: 2310000 | G14: 2750000
B15: Sponsorship & naming rights | C15: 1000000 | D15: 1300000 | E15: 1600000 | F15: 1800000 | G15: 2000000
B16: Corporate events & private hire | C16: 1000000 | D16: 1200000 | E16: 1400000 | F16: 1600000 | G16: 1800000
B17: Conference & event hosting | C17: 300000 | D17: 500000 | E17: 700000 | F17: 850000 | G17: 1000000
B18: Education — courses & field trips | C18: 900000 | D18: 1100000 | E18: 1300000 | F18: 1400000 | G18: 1500000
... B22: Traveling-exhibit licensing | C22: 50000 | D22: 100000 | E22: 200000 | F22: 300000 | G22: 400000
B23: NONEXCHANGE / NONOPERATING
B24: Grants (nonexchange, GASB 33) | C24: 300000 | D24: 300000 | E24: 300000 | F24: 300000 | G24: 300000
B25: OPERATING EXPENSES (excl. depreciation)
B26: Payroll & staff | C26: 6941250 | D26: 7562500 | E26: 8668750 | F26: 8946250 | G26: 9332500
B27: Rent / lease | C27: 1620000 | D27: 1669000 | E27: 1719000 | F27: 1771000 | G27: 1824000
B28: Utilities | C28: 600000 | D28: 620000 | E28: 640000 | F28: 660000 | G28: 680000
B29: Marketing | C29: 2500000 | D29: 2000000 | E29: 1800000 | F29: 1800000 | G29: 1800000
B30: Show production & new content | C30: 800000 | D30: 900000 | E30: 1000000 | F30: 1000000 | G30: 1000000
B31: Insurance | C31: 400000 | D31: 420000 | E31: 440000 | F31: 460000 | G31: 480000
B32: Facility & AV maintenance | C32: 600000 | D32: 700000 | E32: 800000 | F32: 850000 | G32: 900000
B33: G&A / other | C33: 1200000 | D33: 1300000 | E33: 1400000 | F33: 1500000 | G33: 1600000
B34: Outsourced services | C34: 930000 | D34: 1000000 | E34: 1060000 | F34: 1120000 | G34: 1180000
B35: Robot maintenance | C35: 1634400 | D35: 1940400 | E35: 2246400 | F35: 2552400 | G35: 2858400
B36: Retail COGS | C36: 742500 | D36: 832500 | E36: 990000 | F36: 1125000 | G36: 1215000
B37: F&B COGS | C37: 1876875 | D37: 2104375 | E37: 2502500 | F37: 2843750 | G37: 3071250
... B40: Licensing & IP (placeholder) | C40: 400000 | D40: 400000 | E40: 400000 | F40: 400000 | G40: 400000
B41: OTHER DRIVERS
B42: Depreciation & amortization | C42: 3102800 | D42: 3614466.7 | E42: 4126133.3 | F42: 4637800 | G42: 2879466.7
B43: Interest expense (capital debt) | C43: 480000 | D43: 480000 | E43: 480000 | F43: 480000 | G43: 480000
B44: Capital assets, net (NBV from v13) | C44: 15469200 | D44: 14654733 | E44: 13328600 | F44: 11490800 | G44: 11411333
B45: Capital asset acquisitions (depreciable capex) | C45: 18572000 | D45: 2800000 | E45: 2800000 | F45: 2800000 | G45: 2800000
B46: Long-term debt outstanding | C46: 6000000 | D46: 6000000 | E46: 6000000 | F46: 6000000 | G46: 6000000
B47: Capital debt drawn (proceeds) | C47: 6000000 | D47: 0 | E47: 0 | F47: 0 | G47: 0
...
